<?xml version="1.0" ?>
<!-- =================================================================================== -->
<!-- |    This document was autogenerated by xacro from er3.xacro                      | -->
<!-- |    EDITING THIS FILE BY HAND IS NOT RECOMMENDED                                 | -->
<!-- =================================================================================== -->
<robot name="er3" xmlns:xacro="http://www.ros.org/wiki/xacro">
  <!-- Space btw top of beam and the each joint -->
  
#  
  <!-- Import Rviz colors -->
  <!-- Used for fixing robot to Gazebo 'base_link' -->
  <link name="world"/>
  <link name="camera_link">
    <collision>
      <origin rpy="0.0 0 0" xyz="0 0 0"/>
      <geometry>
        <cylinder length="0.0" radius="0.0"/>
      </geometry>
    </collision>
    <visual>
      <origin rpy="0.0 0 0" xyz="0 0 0"/>
      <geometry>
        <cylinder length="0.0" radius="0.0"/>
      </geometry>
    </visual>
    <inertial>
      <origin rpy="0 0 0" xyz="0 0 0"/>
      <mass value="0.1"/>
      <inertia ixx="1.0" ixy="0.0" ixz="0.0" iyy="1.0" iyz="0.0" izz="1.0"/>
    </inertial>
  </link>
  <joint name="joint_camera" type="fixed">
    <parent link="world"/>
    <child link="camera_link"/>
    <axis xyz="1 0 0"/>
    <origin rpy="0 0 0" xyz="-0.4 0 0.4"/>
  </joint>
  <joint name="joint_base" type="fixed">
    <parent link="world"/>
    <child link="link_base"/>
    <origin rpy="0 0 0" xyz="0 0 0.0"/>
  </joint>
  <!-- Link base-->
  <link name="link_base">
    <collision>
      <origin rpy="0.0 0 0" xyz="0 0 0"/>
      <geometry>
        <cylinder length="0.0" radius="0.0"/>
      </geometry>
    </collision>
    <visual>
      <origin rpy="0.0 0 0" xyz="-0.02488 0.020461 -0.18407"/>
      <geometry>
        <mesh filename="package://er3_description/mesh/base.dae"/>
      </geometry>
    </visual>
    <inertial>
      <origin rpy="0 0 0" xyz="0 0 0"/>
      <mass value="0.1"/>
      <inertia ixx="1.0" ixy="0.0" ixz="0.0" iyy="1.0" iyz="0.0" izz="1.0"/>
    </inertial>
  </link>
  <joint name="joint_1" type="revolute">
    <parent link="link_base"/>
    <child link="link_1"/>
    <axis xyz="0 0 1"/>
    <origin rpy="0 0 0" xyz="0 0 0.0"/>
    <dynamics damping="0.7"/>
    <limit effort="1000.0" lower="-2.9147" upper="2.9147" velocity="0.1"/>
  </joint>
  <!-- Link 1-->
  <link name="link_1">
    <collision>
      <origin rpy="0.0 0 0" xyz="0 0 0"/>
      <geometry>
        <cylinder length="0.0" radius="0.0"/>
      </geometry>
    </collision>
    <visual>
      <origin rpy="0.0 0 0" xyz="-0.02488 0.020461 -0.18407"/>
      <geometry>
        <mesh filename="package://er3_description/mesh/1_axis.dae"/>
      </geometry>
    </visual>
    <inertial>
      <origin rpy="0 0 0" xyz="0 0 0.0"/>
      <mass value="0.1"/>
      <inertia ixx="1.0" ixy="0.0" ixz="0.0" iyy="1.0" iyz="0.0" izz="1.0"/>
    </inertial>
  </link>
  <!-- Joint 2-->
  <joint name="joint_2" type="revolute">
    <parent link="link_1"/>
    <child link="link_2"/>
    <origin rpy="-1.57079632679 0 0" xyz="0.05 0 0.3215"/>
    <axis xyz="0 0 1"/>
    <dynamics damping="0.7"/>
    <limit effort="1000.0" lower="-2.2689" upper="1.5707963267948966192313216916398" velocity="0.1"/>
  </joint>
  <!-- Link 2-->
  <link name="link_2">
    <collision>
      <origin rpy="0.0 0 0" xyz="0 0 0"/>
      <geometry>
        <cylinder length="0.0" radius="0.0"/>
      </geometry>
    </collision>
    <visual>
      <origin rpy="1.57079632679 0 0" xyz="-0.07351 0.50557 0.019211"/>
      <geometry>
        <mesh filename="package://er3_description/mesh/2_axis.dae"/>
      </geometry>
    </visual>
    <inertial>
      <origin rpy="0 0 0" xyz="0 -0.12 0"/>
      <mass value="0.1"/>
      <inertia ixx="1.0" ixy="0.0" ixz="0.0" iyy="1.0" iyz="0.0" izz="1.0"/>
    </inertial>
  </link>
  <!-- Joint 3-->
  <joint name="joint_3" type="revolute">
    <parent link="link_2"/>
    <child link="link_3"/>
    <origin rpy="0 0 -1.57079632679" xyz="0 -0.27 0"/>
    <axis xyz="0 0 1"/>
    <dynamics damping="0.7"/>
    <limit effort="1000.0" lower="-1.3090" upper="1.832595714594046055769875306913" velocity="0.1"/>
  </joint>
  <!-- Link 3-->
  <link name="link_3">
    <collision>
      <origin rpy="0.0 0 0" xyz="0 0 0"/>
      <geometry>
        <cylinder length="0.0" radius="0.0"/>
      </geometry>
    </collision>
    <visual>
      <origin rpy="1.57079632679 0 1.57079632679" xyz="-0.77346 -0.054782 0.014961"/>
      <geometry>
        <mesh filename="package://er3_description/mesh/3_axis.dae"/>
      </geometry>
    </visual>
    <inertial>
      <origin rpy="0 0 0" xyz="0 0 0"/>
      <mass value="0.1"/>
      <inertia ixx="1.0" ixy="0.0" ixz="0.0" iyy="1.0" iyz="0.0" izz="1.0"/>
    </inertial>
  </link>
  <!-- Joint 4-->
  <joint name="joint_4" type="revolute">
    <parent link="link_3"/>
    <child link="link_4"/>
    <origin rpy="1.57079632679 0 0" xyz="0.07 0.299 0"/>
    <axis xyz="0 0 1"/>
    <dynamics damping="0.7"/>
    <limit effort="1000.0" lower="-3.1415926535897932384626433832795" upper="3.1415926535897932384626433832795" velocity="0.1"/>
  </joint>
  <!-- Link 4-->
  <link name="link_4">
    <collision>
      <origin rpy="0.0 0 0" xyz="0 0 0"/>
      <geometry>
        <cylinder length="0.0" radius="0.0"/>
      </geometry>
    </collision>
    <visual>
      <origin rpy="0.0 1.5708 0" xyz="-0.870 0.034255 0.473982"/>
      <geometry>
        <mesh filename="package://er3_description/mesh/4_axis.dae"/>
      </geometry>
    </visual>
    <inertial>
      <origin rpy="0 0 0" xyz="0 0 0.135"/>
      <mass value="0.1"/>
      <inertia ixx="1.0" ixy="0.0" ixz="0.0" iyy="1.0" iyz="0.0" izz="1.0"/>
    </inertial>
  </link>
  <!-- Joint 5-->
  <joint name="joint_5" type="revolute">
    <parent link="link_4"/>
    <child link="link_5"/>
    <axis xyz="0 0 1"/>
    <dynamics damping="0.7"/>
    <origin rpy="1.57079632679 0 0" xyz="0 0 0.0"/>
    <limit effort="1000.0" lower="-1.9199" upper="1.9199" velocity="0.1"/>
  </joint>
  <!-- Link 5-->
  <link name="link_5">
    <collision>
      <origin rpy="0.0 0 0" xyz="0 0 0"/>
      <geometry>
        <cylinder length="0.0" radius="0.0"/>
      </geometry>
    </collision>
    <visual>
      <origin rpy="-1.57079632679 0 -1.57079632679" xyz="-0.86313 0.347386 -0.01926"/>
      <geometry>
        <mesh filename="package://er3_description/mesh/5_axis.dae"/>
      </geometry>
    </visual>
    <inertial>
      <origin rpy="0 0 0" xyz="0 0 0"/>
      <mass value="0.1"/>
      <inertia ixx="1.0" ixy="0.0" ixz="0.0" iyy="1.0" iyz="0.0" izz="1.0"/>
    </inertial>
  </link>
  <!-- Joint 6-->
  <joint name="joint_6" type="revolute">
    <parent link="link_5"/>
    <child link="link_6"/>
    <axis xyz="0 0 1"/>
    <dynamics damping="0.7"/>
    <origin rpy="1.57079632679 0 0" xyz="0 0 0.0"/>
    <limit effort="1000.0" lower="-6.283185307180000123139507" upper="6.283185307180000123139507" velocity="0.1"/>
  </joint>
  <!-- Link 6-->
  <link name="link_6">
    <collision>
      <origin rpy="0.0 0 0" xyz="0 0 0"/>
      <geometry>
        <cylinder length="0.0" radius="0.0"/>
      </geometry>
    </collision>
    <visual>
      <origin rpy="0.0 -1.5041 0.0" xyz="0.83608 0.01926 -0.425 "/>
      <geometry>
        <mesh filename="package://er3_description/mesh/6_axis.dae"/>
      </geometry>
    </visual>
    <inertial>
      <origin rpy="0 0 0" xyz="0 0 0.09"/>
      <mass value="0.1"/>
      <inertia ixx="1.0" ixy="0.0" ixz="0.0" iyy="1.0" iyz="0.0" izz="1.0"/>
    </inertial>
  </link>
  <!-- Joint 7-->
  <joint name="joint_7" type="fixed">
    <parent link="link_6"/>
    <child link="link_end"/>
    <axis xyz="0 0 1"/>
    <origin rpy="0 0 0" xyz="0 0 0"/>
  </joint>
  <!-- Link end-->
  <link name="link_end">
    <collision>
      <origin rpy="0.0 0 0" xyz="0 0 0"/>
      <geometry>
        <cylinder length="0.0" radius="0.0"/>
      </geometry>
    </collision>
  </link>
</robot>

